package com.TimeSpaceWarrior.TemporalLightMod.world.structure;

import com.TimeSpaceWarrior.TemporalLightMod.BlockRegistry;
import com.TimeSpaceWarrior.TemporalLightMod.ItemRegistry;
import net.minecraft.block.BlockAnvil;
import net.minecraft.init.Blocks;
import net.minecraft.init.Items;
import net.minecraft.item.ItemStack;
import net.minecraft.tileentity.TileEntityChest;
import net.minecraft.tileentity.TileEntityHopper;
import net.minecraft.tileentity.TileEntitySign;
import net.minecraft.world.World;
import net.minecraft.world.gen.feature.WorldGenerator;

import java.util.Random;

public class cedric_base extends WorldGenerator {
    @Override
    public boolean generate(World world, Random random, int x, int y, int z) {
        x-=29;//offset the generation
        z-=11;//offset the generation

        world.setBlock(x+29,y+0,z+11,BlockRegistry.MAGIWOODLOG,0,2);
        world.setBlock(x+29,y+1,z+11,BlockRegistry.MAGIWOODLOG,0,2);
        world.setBlock(x+29,y+2,z+11,BlockRegistry.MAGIWOODLOG,0,2);
        world.setBlock(x+29,y+3,z+11,BlockRegistry.MAGIWOODLOG,0,2);
        world.setBlock(x+29,y+4,z+11,BlockRegistry.MAGIWOODLOG,0,2);
        world.setBlock(x+29,y+5,z+11,BlockRegistry.MAGIWOODLOG,0,2);
        world.setBlock(x+29,y+6,z+11,BlockRegistry.MAGIWOODLOG,0,2);
        world.setBlock(x+29,y+7,z+11,BlockRegistry.MAGIWOODLOG,0,2);
        world.setBlock(x+29,y+8,z+11,BlockRegistry.MAGIWOODLOG,0,2);
        world.setBlock(x+28,y+9,z+10,BlockRegistry.LIGHTSTEEL_STAIRS,6,2);
        world.setBlock(x+29,y+9,z+10,BlockRegistry.LIGHTSTEEL_STAIRS,6,2);
        world.setBlock(x+30,y+9,z+10,BlockRegistry.LIGHTSTEEL_STAIRS,6,2);
        world.setBlock(x+28,y+9,z+11,BlockRegistry.LIGHTSTEEL_STAIRS,4,2);
        world.setBlock(x+29,y+9,z+11,BlockRegistry.MAGIWOODLOG,0,2);
        world.setBlock(x+30,y+9,z+11,BlockRegistry.LIGHTSTEEL_STAIRS,5,2);
        world.setBlock(x+28,y+9,z+12,BlockRegistry.LIGHTSTEEL_STAIRS,7,2);
        world.setBlock(x+29,y+9,z+12,BlockRegistry.LIGHTSTEEL_STAIRS,7,2);
        world.setBlock(x+30,y+9,z+12,BlockRegistry.LIGHTSTEEL_STAIRS,7,2);
        world.setBlock(x+28,y+10,z+9,BlockRegistry.MAGIWOODLEAVES);
        world.setBlock(x+29,y+10,z+9,BlockRegistry.MAGIWOODLEAVES);
        world.setBlock(x+30,y+10,z+9,BlockRegistry.MAGIWOODLEAVES);
        world.setBlock(x+27,y+10,z+10,BlockRegistry.MAGIWOODLEAVES);
        world.setBlock(x+28,y+10,z+10,BlockRegistry.MAGIWOODLEAVES);
        world.setBlock(x+29,y+10,z+10,BlockRegistry.MAGIWOODLEAVES);
        world.setBlock(x+30,y+10,z+10,BlockRegistry.MAGIWOODLEAVES);
        world.setBlock(x+31,y+10,z+10,BlockRegistry.MAGIWOODLEAVES);
        world.setBlock(x+27,y+10,z+11,BlockRegistry.MAGIWOODLEAVES);
        world.setBlock(x+28,y+10,z+11,BlockRegistry.MAGIWOODLEAVES);
        world.setBlock(x+29,y+10,z+11,BlockRegistry.MAGIWOODLEAVES);
        world.setBlock(x+30,y+10,z+11,BlockRegistry.MAGIWOODLEAVES);
        world.setBlock(x+31,y+10,z+11,BlockRegistry.MAGIWOODLEAVES);
        world.setBlock(x+27,y+10,z+12,BlockRegistry.MAGIWOODLEAVES);
        world.setBlock(x+28,y+10,z+12,BlockRegistry.MAGIWOODLEAVES);
        world.setBlock(x+29,y+10,z+12,BlockRegistry.MAGIWOODLEAVES);
        world.setBlock(x+30,y+10,z+12,BlockRegistry.MAGIWOODLEAVES);
        world.setBlock(x+31,y+10,z+12,BlockRegistry.MAGIWOODLEAVES);
        world.setBlock(x+28,y+10,z+13,BlockRegistry.MAGIWOODLEAVES);
        world.setBlock(x+29,y+10,z+13,BlockRegistry.MAGIWOODLEAVES);
        world.setBlock(x+30,y+10,z+13,BlockRegistry.MAGIWOODLEAVES);
        world.setBlock(x+28,y+11,z+8,BlockRegistry.LIGHTSTEEL_STAIRS,6,2);
        world.setBlock(x+29,y+11,z+8,BlockRegistry.LIGHTSTEEL_STAIRS,6,2);
        world.setBlock(x+30,y+11,z+8,BlockRegistry.LIGHTSTEEL_STAIRS,6,2);
        world.setBlock(x+27,y+11,z+9,BlockRegistry.MAGIWOODLOG);
        world.setBlock(x+28,y+11,z+9,BlockRegistry.MAGIWOODPLANK);
        world.setBlock(x+29,y+11,z+9,BlockRegistry.MAGIWOODLOG);
        world.setBlock(x+30,y+11,z+9,BlockRegistry.MAGIWOODPLANK);
        world.setBlock(x+31,y+11,z+9,BlockRegistry.MAGIWOODLOG);
        world.setBlock(x+26,y+11,z+10,BlockRegistry.LIGHTSTEEL_STAIRS,4,2);
        world.setBlock(x+27,y+11,z+10,BlockRegistry.MAGIWOODPLANK);
        world.setBlock(x+28,y+11,z+10,BlockRegistry.MAGIWOODLOG);
        world.setBlock(x+29,y+11,z+10,BlockRegistry.MAGIWOODPLANK);
        world.setBlock(x+30,y+11,z+10,BlockRegistry.MAGIWOODLOG);
        world.setBlock(x+31,y+11,z+10,BlockRegistry.MAGIWOODPLANK);
        world.setBlock(x+32,y+11,z+10,BlockRegistry.LIGHTSTEEL_STAIRS,5,2);
        world.setBlock(x+26,y+11,z+11,BlockRegistry.LIGHTSTEEL_STAIRS,4,2);
        world.setBlock(x+27,y+11,z+11,BlockRegistry.MAGIWOODLOG);
        world.setBlock(x+28,y+11,z+11,BlockRegistry.MAGIWOODPLANK);
        world.setBlock(x+29,y+11,z+11,Blocks.glowstone);
        world.setBlock(x+30,y+11,z+11,BlockRegistry.MAGIWOODPLANK);
        world.setBlock(x+31,y+11,z+11,BlockRegistry.MAGIWOODLOG);
        world.setBlock(x+32,y+11,z+11,BlockRegistry.LIGHTSTEEL_STAIRS,5,2);
        world.setBlock(x+26,y+11,z+12,BlockRegistry.LIGHTSTEEL_STAIRS,4,2);
        world.setBlock(x+27,y+11,z+12,BlockRegistry.MAGIWOODPLANK);
        world.setBlock(x+28,y+11,z+12,BlockRegistry.MAGIWOODLOG);
        world.setBlock(x+29,y+11,z+12,BlockRegistry.MAGIWOODPLANK);
        world.setBlock(x+30,y+11,z+12,BlockRegistry.MAGIWOODLOG);
        world.setBlock(x+31,y+11,z+12,BlockRegistry.MAGIWOODPLANK);
        world.setBlock(x+32,y+11,z+12,BlockRegistry.LIGHTSTEEL_STAIRS,5,2);
        world.setBlock(x+27,y+11,z+13,BlockRegistry.MAGIWOODLOG);
        world.setBlock(x+28,y+11,z+13,BlockRegistry.MAGIWOODPLANK);
        world.setBlock(x+29,y+11,z+13,BlockRegistry.MAGIWOODLOG);
        world.setBlock(x+30,y+11,z+13,BlockRegistry.MAGIWOODPLANK);
        world.setBlock(x+31,y+11,z+13,BlockRegistry.MAGIWOODLOG);
        world.setBlock(x+28,y+11,z+14,BlockRegistry.LIGHTSTEEL_STAIRS,7,2);
        world.setBlock(x+29,y+11,z+14,BlockRegistry.LIGHTSTEEL_STAIRS,7,2);
        world.setBlock(x+30,y+11,z+14,BlockRegistry.LIGHTSTEEL_STAIRS,7,2);
        world.setBlock(x+28,y+12,z+1,BlockRegistry.LIGHTSTEEL_BLOCK);
        world.setBlock(x+29,y+12,z+1,BlockRegistry.LIGHTSTEEL_BLOCK);
        world.setBlock(x+30,y+12,z+1,BlockRegistry.LIGHTSTEEL_BLOCK);
        world.setBlock(x+28,y+12,z+2,BlockRegistry.LIGHTSTEEL_BLOCK);
        world.setBlock(x+29,y+12,z+2,BlockRegistry.LIGHTSTEEL_BLOCK);
        world.setBlock(x+30,y+12,z+2,BlockRegistry.LIGHTSTEEL_BLOCK);
        world.setBlock(x+28,y+12,z+3,BlockRegistry.LIGHTSTEEL_BLOCK);
        world.setBlock(x+29,y+12,z+3,BlockRegistry.LIGHTSTEEL_BLOCK);
        world.setBlock(x+30,y+12,z+3,BlockRegistry.LIGHTSTEEL_BLOCK);
        world.setBlock(x+29,y+12,z+4,BlockRegistry.MAGIWOODPLANK);
        world.setBlock(x+29,y+12,z+5,BlockRegistry.MAGIWOODPLANK);
        world.setBlock(x+29,y+12,z+6,BlockRegistry.MAGIWOODPLANK);
        world.setBlock(x+29,y+12,z+7,BlockRegistry.MAGIWOODPLANK);
        world.setBlock(x+28,y+12,z+8,BlockRegistry.MAGIWOODPLANK);
        world.setBlock(x+29,y+12,z+8,BlockRegistry.MAGIWOODLOG);
        world.setBlock(x+30,y+12,z+8,BlockRegistry.MAGIWOODPLANK);
        world.setBlock(x+27,y+12,z+9,BlockRegistry.MAGIWOODLOG);
        world.setBlock(x+28,y+12,z+9,BlockRegistry.LIGHTSTEEL_STAIRS,3,2);
        world.setBlock(x+29,y+12,z+9,BlockRegistry.LIGHTSTEEL_STAIRS,3,2);
        world.setBlock(x+30,y+12,z+9,BlockRegistry.LIGHTSTEEL_STAIRS,3,2);
        world.setBlock(x+31,y+12,z+9,BlockRegistry.MAGIWOODLOG);
        world.setBlock(x+19,y+12,z+10,BlockRegistry.LIGHTSTEEL_BLOCK);
        world.setBlock(x+20,y+12,z+10,BlockRegistry.LIGHTSTEEL_BLOCK);
        world.setBlock(x+21,y+12,z+10,BlockRegistry.LIGHTSTEEL_BLOCK);
        world.setBlock(x+26,y+12,z+10,BlockRegistry.MAGIWOODPLANK);
        world.setBlock(x+27,y+12,z+10,BlockRegistry.LIGHTSTEEL_STAIRS,1,2);
        world.setBlock(x+31,y+12,z+10,BlockRegistry.LIGHTSTEEL_STAIRS,0,2);
        world.setBlock(x+32,y+12,z+10,BlockRegistry.MAGIWOODPLANK);
        world.setBlock(x+35,y+12,z+10,BlockRegistry.MAGIWOODPLANK);
        world.setBlock(x+36,y+12,z+10,BlockRegistry.LIGHTSTEEL_BLOCK);
        world.setBlock(x+37,y+12,z+10,BlockRegistry.LIGHTSTEEL_BLOCK);
        world.setBlock(x+38,y+12,z+10,BlockRegistry.LIGHTSTEEL_BLOCK);
        world.setBlock(x+19,y+12,z+11,BlockRegistry.LIGHTSTEEL_BLOCK);
        world.setBlock(x+20,y+12,z+11,BlockRegistry.LIGHTSTEEL_BLOCK);
        world.setBlock(x+21,y+12,z+11,BlockRegistry.LIGHTSTEEL_BLOCK);
        world.setBlock(x+22,y+12,z+11,BlockRegistry.MAGIWOODPLANK);
        world.setBlock(x+23,y+12,z+11,BlockRegistry.MAGIWOODPLANK);
        world.setBlock(x+24,y+12,z+11,BlockRegistry.MAGIWOODPLANK);
        world.setBlock(x+25,y+12,z+11,BlockRegistry.MAGIWOODPLANK);
        world.setBlock(x+26,y+12,z+11,BlockRegistry.MAGIWOODLOG);
        world.setBlock(x+27,y+12,z+11,BlockRegistry.LIGHTSTEEL_STAIRS,1,2);
        world.setBlock(x+31,y+12,z+11,BlockRegistry.LIGHTSTEEL_STAIRS,0,2);
        world.setBlock(x+32,y+12,z+11,BlockRegistry.MAGIWOODLOG);
        world.setBlock(x+33,y+12,z+11,BlockRegistry.MAGIWOODPLANK);
        world.setBlock(x+34,y+12,z+11,BlockRegistry.MAGIWOODPLANK);
        world.setBlock(x+35,y+12,z+11,BlockRegistry.MAGIWOODPLANK);
        world.setBlock(x+36,y+12,z+11,BlockRegistry.LIGHTSTEEL_BLOCK);
        world.setBlock(x+37,y+12,z+11,BlockRegistry.LIGHTSTEEL_BLOCK);
        world.setBlock(x+38,y+12,z+11,BlockRegistry.LIGHTSTEEL_BLOCK);
        world.setBlock(x+19,y+12,z+12,BlockRegistry.LIGHTSTEEL_BLOCK);
        world.setBlock(x+20,y+12,z+12,BlockRegistry.LIGHTSTEEL_BLOCK);
        world.setBlock(x+21,y+12,z+12,BlockRegistry.LIGHTSTEEL_BLOCK);
        world.setBlock(x+26,y+12,z+12,BlockRegistry.MAGIWOODPLANK);
        world.setBlock(x+27,y+12,z+12,BlockRegistry.LIGHTSTEEL_STAIRS,1,2);
        world.setBlock(x+31,y+12,z+12,BlockRegistry.LIGHTSTEEL_STAIRS,0,2);
        world.setBlock(x+32,y+12,z+12,BlockRegistry.MAGIWOODPLANK);
        world.setBlock(x+35,y+12,z+12,BlockRegistry.MAGIWOODPLANK);
        world.setBlock(x+36,y+12,z+12,BlockRegistry.LIGHTSTEEL_BLOCK);
        world.setBlock(x+37,y+12,z+12,BlockRegistry.LIGHTSTEEL_BLOCK);
        world.setBlock(x+38,y+12,z+12,BlockRegistry.LIGHTSTEEL_BLOCK);
        world.setBlock(x+27,y+12,z+13,BlockRegistry.MAGIWOODLOG);
        world.setBlock(x+28,y+12,z+13,BlockRegistry.LIGHTSTEEL_STAIRS,2,2);
        world.setBlock(x+29,y+12,z+13,BlockRegistry.LIGHTSTEEL_STAIRS,2,2);
        world.setBlock(x+30,y+12,z+13,BlockRegistry.LIGHTSTEEL_STAIRS,2,2);
        world.setBlock(x+31,y+12,z+13,BlockRegistry.MAGIWOODLOG);
        world.setBlock(x+28,y+12,z+14,BlockRegistry.MAGIWOODPLANK);
        world.setBlock(x+29,y+12,z+14,BlockRegistry.MAGIWOODLOG);
        world.setBlock(x+30,y+12,z+14,BlockRegistry.MAGIWOODPLANK);
        world.setBlock(x+29,y+12,z+15,BlockRegistry.MAGIWOODPLANK);
        world.setBlock(x+29,y+12,z+16,BlockRegistry.MAGIWOODPLANK);
        world.setBlock(x+29,y+12,z+17,BlockRegistry.MAGIWOODPLANK);
        world.setBlock(x+29,y+12,z+18,BlockRegistry.MAGIWOODPLANK);
        world.setBlock(x+28,y+12,z+19,BlockRegistry.LIGHTSTEEL_BLOCK);
        world.setBlock(x+29,y+12,z+19,Blocks.glowstone);
        world.setBlock(x+30,y+12,z+19,BlockRegistry.LIGHTSTEEL_BLOCK);
        world.setBlock(x+28,y+12,z+20,Blocks.glowstone);
        world.setBlock(x+29,y+12,z+20,BlockRegistry.LIGHTSTEEL_BLOCK);
        world.setBlock(x+30,y+12,z+20,Blocks.glowstone);
        world.setBlock(x+28,y+12,z+21,BlockRegistry.LIGHTSTEEL_BLOCK);
        world.setBlock(x+29,y+12,z+21,Blocks.glowstone);
        world.setBlock(x+30,y+12,z+21,BlockRegistry.LIGHTSTEEL_BLOCK);
        world.setBlock(x+28,y+13,z+0,BlockRegistry.MAGIWOODPLANK);
        world.setBlock(x+29,y+13,z+0,BlockRegistry.MAGIWOODPLANK);
        world.setBlock(x+30,y+13,z+0,BlockRegistry.MAGIWOODPLANK);
        world.setBlock(x+27,y+13,z+1,BlockRegistry.MAGIWOODPLANK);
        world.setBlock(x+31,y+13,z+1,BlockRegistry.MAGIWOODPLANK);
        world.setBlock(x+27,y+13,z+2,BlockRegistry.MAGIWOODPLANK);
        world.setBlock(x+29,y+13,z+2,Blocks.crafting_table);
        world.setBlock(x+31,y+13,z+2,BlockRegistry.MAGIWOODPLANK);
        world.setBlock(x+27,y+13,z+3,BlockRegistry.MAGIWOODPLANK);
        world.setBlock(x+31,y+13,z+3,BlockRegistry.MAGIWOODPLANK);
        world.setBlock(x+28,y+13,z+4,BlockRegistry.MAGIWOODPLANK);
        world.setBlock(x+30,y+13,z+4,BlockRegistry.MAGIWOODPLANK);
        world.setBlock(x+28,y+13,z+7,Blocks.chest);
        world.setBlock(x+30,y+13,z+7,Blocks.chest);
        world.setBlock(x+28,y+13,z+8,BlockRegistry.MAGIWOODLOG);
        world.setBlock(x+30,y+13,z+8,BlockRegistry.MAGIWOODLOG);
        world.setBlock(x+27,y+13,z+9,BlockRegistry.MAGIWOODLOG);
        world.setBlock(x+31,y+13,z+9,BlockRegistry.MAGIWOODLOG);
        world.setBlock(x+36,y+13,z+9,BlockRegistry.MAGIWOODPLANK);
        world.setBlock(x+37,y+13,z+9,BlockRegistry.MAGIWOODPLANK);
        world.setBlock(x+38,y+13,z+9,BlockRegistry.MAGIWOODPLANK);
        world.setBlock(x+19,y+13,z+10,Blocks.chest);
        world.setBlock(x+25,y+13,z+10,Blocks.chest);
        world.setBlock(x+26,y+13,z+10,BlockRegistry.MAGIWOODLOG);
        world.setBlock(x+32,y+13,z+10,BlockRegistry.MAGIWOODLOG);
        world.setBlock(x+33,y+13,z+10,Blocks.chest);
        world.setBlock(x+35,y+13,z+10,BlockRegistry.MAGIWOODPLANK);
        world.setBlock(x+39,y+13,z+10,BlockRegistry.MAGIWOODPLANK);
        world.setBlock(x+37,y+13,z+11,Blocks.anvil,2,2);
        world.setBlock(x+39,y+13,z+11,BlockRegistry.MAGIWOODPLANK);
        world.setBlock(x+19,y+13,z+12,Blocks.chest);
        world.setBlock(x+25,y+13,z+12,Blocks.chest);
        world.setBlock(x+26,y+13,z+12,BlockRegistry.MAGIWOODLOG);
        world.setBlock(x+32,y+13,z+12,BlockRegistry.MAGIWOODLOG);
        world.setBlock(x+33,y+13,z+12,Blocks.chest);
        world.setBlock(x+35,y+13,z+12,BlockRegistry.MAGIWOODPLANK);
        world.setBlock(x+39,y+13,z+12,BlockRegistry.MAGIWOODPLANK);
        world.setBlock(x+27, y+13, z+13,BlockRegistry.MAGIWOODLOG);
        world.setBlock(x+31,y+13,z+13,BlockRegistry.MAGIWOODLOG);
        world.setBlock(x+36,y+13,z+13,BlockRegistry.MAGIWOODPLANK);
        world.setBlock(x+37,y+13,z+13,BlockRegistry.MAGIWOODPLANK);
        world.setBlock(x+38,y+13,z+13,BlockRegistry.MAGIWOODPLANK);
        world.setBlock(x+39,y+13,z+13,BlockRegistry.MAGIWOODPLANK);
        world.setBlock(x+28,y+13,z+14,BlockRegistry.MAGIWOODLOG);
        world.setBlock(x+30,y+13,z+14,BlockRegistry.MAGIWOODLOG);
        world.setBlock(x+37,y+13,z+14,BlockRegistry.MAGIWOODPLANK);
        world.setBlock(x+28,y+13,z+15,Blocks.chest);
        world.setBlock(x+30,y+13,z+15,Blocks.chest);
        world.setBlock(x+37,y+13,z+15,BlockRegistry.MAGIWOODPLANK);
        world.setBlock(x+37,y+13,z+16,BlockRegistry.MAGIWOODPLANK);
        world.setBlock(x+35,y+13,z+17,BlockRegistry.MAGIWOODPLANK);
        world.setBlock(x+36,y+13,z+17,BlockRegistry.MAGIWOODPLANK);
        world.setBlock(x+37,y+13,z+17,BlockRegistry.MAGIWOODPLANK);
        world.setBlock(x+38,y+13,z+17,BlockRegistry.MAGIWOODPLANK);
        world.setBlock(x+39,y+13,z+17,BlockRegistry.MAGIWOODPLANK);
        world.setBlock(x+28,y+13,z+18,Blocks.bookshelf);
        world.setBlock(x+29,y+13,z+18,Blocks.bookshelf);
        world.setBlock(x+30,y+13,z+18,Blocks.bookshelf);
        world.setBlock(x+35,y+13,z+18,BlockRegistry.MAGIWOODPLANK);
        world.setBlock(x+36,y+13,z+18,BlockRegistry.MAGIWOODPLANK);
        world.setBlock(x+37,y+13,z+18,BlockRegistry.MAGIWOODPLANK);
        world.setBlock(x+38,y+13,z+18,BlockRegistry.MAGIWOODPLANK);
        world.setBlock(x+39,y+13,z+18,BlockRegistry.MAGIWOODPLANK);
        world.setBlock(x+27,y+13,z+19,Blocks.bookshelf);
        world.setBlock(x+31,y+13,z+19,Blocks.bookshelf);
        world.setBlock(x+35,y+13,z+19,BlockRegistry.MAGIWOODPLANK);
        world.setBlock(x+36,y+13,z+19,BlockRegistry.MAGIWOODPLANK);
        world.setBlock(x+37,y+13,z+19,BlockRegistry.MAGIWOODPLANK);
        world.setBlock(x+38,y+13,z+19,BlockRegistry.MAGIWOODPLANK);
        world.setBlock(x+39,y+13,z+19,BlockRegistry.MAGIWOODPLANK);
        world.setBlock(x+27,y+13,z+20,Blocks.bookshelf);
        world.setBlock(x+29,y+13,z+20,Blocks.enchanting_table);
        world.setBlock(x+31,y+13,z+20,Blocks.bookshelf);
        world.setBlock(x+35, y+13, z+20,BlockRegistry.MAGIWOODPLANK);
        world.setBlock(x+36, y+13, z+20,BlockRegistry.MAGIWOODPLANK);
        world.setBlock(x+37, y+13, z+20,BlockRegistry.MAGIWOODPLANK);
        world.setBlock(x+38, y+13, z+20,BlockRegistry.MAGIWOODPLANK);
        world.setBlock(x+39, y+13, z+20,BlockRegistry.MAGIWOODPLANK);
        world.setBlock(x+27, y+13, z+21,Blocks.bookshelf);
        world.setBlock(x+31, y+13, z+21,Blocks.bookshelf);
        world.setBlock(x+35, y+13, z+21,BlockRegistry.MAGIWOODPLANK);
        world.setBlock(x+36, y+13, z+21,BlockRegistry.MAGIWOODPLANK);
        world.setBlock(x+37, y+13, z+21,BlockRegistry.MAGIWOODPLANK);
        world.setBlock(x+38, y+13, z+21,BlockRegistry.MAGIWOODPLANK);
        world.setBlock(x+39, y+13, z+21,BlockRegistry.MAGIWOODPLANK);
        world.setBlock(x+28, y+13, z+22,Blocks.bookshelf);
        world.setBlock(x+29, y+13, z+22,Blocks.bookshelf);
        world.setBlock(x+30, y+13, z+22,Blocks.bookshelf);
        world.setBlock(x+36, y+13, z+22,BlockRegistry.MAGIWOODPLANK);
        world.setBlock(x+37, y+13, z+22,BlockRegistry.MAGIWOODPLANK);
        world.setBlock(x+38, y+13, z+22,BlockRegistry.MAGIWOODPLANK);
        world.setBlock(x+28, y+14, z+0 ,BlockRegistry.MAGIWOODPLANK);
        world.setBlock(x+29, y+14, z+0 ,BlockRegistry.MAGIWOODPLANK);
        world.setBlock(x+30, y+14, z+0 ,BlockRegistry.MAGIWOODPLANK);
        world.setBlock(x+27, y+14, z+1 ,BlockRegistry.MAGIWOODPLANK);
        world.setBlock(x+31, y+14, z+1 ,BlockRegistry.MAGIWOODPLANK);
        world.setBlock(x+27, y+14, z+2 ,BlockRegistry.MAGIWOODPLANK);
        world.setBlock(x+31, y+14, z+2 ,BlockRegistry.MAGIWOODPLANK);
        world.setBlock(x+27, y+14, z+3 ,BlockRegistry.MAGIWOODPLANK);
        world.setBlock(x+31, y+14, z+3 ,BlockRegistry.MAGIWOODPLANK);
        world.setBlock(x+28, y+14, z+4 ,BlockRegistry.MAGIWOODPLANK);
        world.setBlock(x+30, y+14, z+4 ,BlockRegistry.MAGIWOODPLANK);
        world.setBlock(x+28, y+14, z+7 ,Blocks.hopper);
        world.setBlock(x+30, y+14, z+7 ,Blocks.hopper);
        world.setBlock(x+28, y+14, z+8 ,BlockRegistry.MAGIWOODLOG);
        world.setBlock(x+30, y+14, z+8 ,BlockRegistry.MAGIWOODLOG);
        world.setBlock(x+27, y+14, z+9 ,BlockRegistry.MAGIWOODLOG);
        world.setBlock(x+28, y+14, z+9 ,Blocks.redstone_torch);
        world.setBlock(x+30, y+14, z+9 ,Blocks.redstone_torch);
        world.setBlock(x+31, y+14, z+9 ,BlockRegistry.MAGIWOODLOG);
        world.setBlock(x+36, y+14, z+9 ,BlockRegistry.MAGIWOODPLANK);
        world.setBlock(x+37, y+14, z+9 ,BlockRegistry.MAGIWOODPLANK);
        world.setBlock(x+38, y+14, z+9 ,BlockRegistry.MAGIWOODPLANK);
        world.setBlock(x+4 , y+14, z+10,BlockRegistry.HYPERSTEEL_BLOCK);
        world.setBlock(x+5 , y+14, z+10,BlockRegistry.HYPERSTEEL_BLOCK);
        world.setBlock(x+6 , y+14, z+10,BlockRegistry.HYPERSTEEL_BLOCK);
        world.setBlock(x+7 , y+14, z+10,BlockRegistry.HYPERSTEEL_BLOCK);
        world.setBlock(x+8 , y+14, z+10,BlockRegistry.HYPERSTEEL_BLOCK);
        world.setBlock(x+9 , y+14, z+10,BlockRegistry.HYPERSTEEL_BLOCK);
        world.setBlock(x+10, y+14, z+10,BlockRegistry.HYPERSTEEL_BLOCK);
        world.setBlock(x+11, y+14, z+10,BlockRegistry.HYPERSTEEL_BLOCK);
        world.setBlock(x+12, y+14, z+10,BlockRegistry.HYPERSTEEL_BLOCK);
        world.setBlock(x+13, y+14, z+10,BlockRegistry.HYPERSTEEL_BLOCK);
        world.setBlock(x+14, y+14, z+10,BlockRegistry.HYPERSTEEL_BLOCK);
        world.setBlock(x+15, y+14, z+10,BlockRegistry.HYPERSTEEL_BLOCK);
        world.setBlock(x+16, y+14, z+10,BlockRegistry.HYPERSTEEL_BLOCK);
        world.setBlock(x+17, y+14, z+10,BlockRegistry.HYPERSTEEL_BLOCK);
        world.setBlock(x+18, y+14, z+10,BlockRegistry.HYPERSTEEL_BLOCK);
        world.setBlock(x+19, y+14, z+10,Blocks.hopper);
        world.setBlock(x+25, y+14, z+10,Blocks.hopper);
        world.setBlock(x+26, y+14, z+10,BlockRegistry.MAGIWOODLOG);
        world.setBlock(x+27, y+14, z+10,Blocks.redstone_torch);
        world.setBlock(x+31, y+14, z+10,Blocks.redstone_torch);
        world.setBlock(x+32, y+14, z+10,BlockRegistry.MAGIWOODLOG);
        world.setBlock(x+33, y+14, z+10,Blocks.hopper);
        world.setBlock(x+35, y+14, z+10,BlockRegistry.MAGIWOODPLANK);
        world.setBlock(x+39, y+14, z+10,BlockRegistry.MAGIWOODPLANK);
        world.setBlock(x+4 , y+14, z+11,BlockRegistry.HYPERSTEEL_BLOCK);
        world.setBlock(x+5 , y+14, z+11,BlockRegistry.HYPERSTEEL_BLOCK);
        world.setBlock(x+6 , y+14, z+11,BlockRegistry.HYPERSTEEL_BLOCK);
        world.setBlock(x+7 , y+14, z+11,BlockRegistry.HYPERSTEEL_BLOCK);
        world.setBlock(x+8 , y+14, z+11,BlockRegistry.HYPERSTEEL_BLOCK);
        world.setBlock(x+9 , y+14, z+11,BlockRegistry.HYPERSTEEL_BLOCK);
        world.setBlock(x+10, y+14, z+11,BlockRegistry.HYPERSTEEL_BLOCK);
        world.setBlock(x+11, y+14, z+11,BlockRegistry.HYPERSTEEL_BLOCK);
        world.setBlock(x+12, y+14, z+11,BlockRegistry.HYPERSTEEL_BLOCK);
        world.setBlock(x+13, y+14, z+11,BlockRegistry.HYPERSTEEL_BLOCK);
        world.setBlock(x+14, y+14, z+11,BlockRegistry.HYPERSTEEL_BLOCK);
        world.setBlock(x+15, y+14, z+11,BlockRegistry.HYPERSTEEL_BLOCK);
        world.setBlock(x+16, y+14, z+11,BlockRegistry.HYPERSTEEL_BLOCK);
        world.setBlock(x+17, y+14, z+11,BlockRegistry.HYPERSTEEL_BLOCK);
        world.setBlock(x+39, y+14, z+11,BlockRegistry.MAGIWOODPLANK);
        world.setBlock(x+4 , y+14, z+12,BlockRegistry.HYPERSTEEL_BLOCK);
        world.setBlock(x+5 , y+14, z+12,BlockRegistry.HYPERSTEEL_BLOCK);
        world.setBlock(x+6 , y+14, z+12,BlockRegistry.HYPERSTEEL_BLOCK);
        world.setBlock(x+7 , y+14, z+12,BlockRegistry.HYPERSTEEL_BLOCK);
        world.setBlock(x+8 , y+14, z+12,BlockRegistry.HYPERSTEEL_BLOCK);
        world.setBlock(x+9 , y+14, z+12,BlockRegistry.HYPERSTEEL_BLOCK);
        world.setBlock(x+10, y+14, z+12,BlockRegistry.HYPERSTEEL_BLOCK);
        world.setBlock(x+11, y+14, z+12,BlockRegistry.HYPERSTEEL_BLOCK);
        world.setBlock(x+12, y+14, z+12,BlockRegistry.HYPERSTEEL_BLOCK);
        world.setBlock(x+13, y+14, z+12,BlockRegistry.HYPERSTEEL_BLOCK);
        world.setBlock(x+14, y+14, z+12,BlockRegistry.HYPERSTEEL_BLOCK);
        world.setBlock(x+15, y+14, z+12,BlockRegistry.HYPERSTEEL_BLOCK);
        world.setBlock(x+16, y+14, z+12,BlockRegistry.HYPERSTEEL_BLOCK);
        world.setBlock(x+17, y+14, z+12,BlockRegistry.HYPERSTEEL_BLOCK);
        world.setBlock(x+18, y+14, z+12,BlockRegistry.HYPERSTEEL_BLOCK);
        world.setBlock(x+19, y+14, z+12,Blocks.hopper);
        world.setBlock(x+25, y+14, z+12,Blocks.hopper);
        world.setBlock(x+26, y+14, z+12,BlockRegistry.MAGIWOODLOG);
        world.setBlock(x+27, y+14, z+12,Blocks.redstone_torch);
        world.setBlock(x+32, y+14, z+12,BlockRegistry.MAGIWOODLOG);
        world.setBlock(x+31, y+14, z+12,Blocks.redstone_torch,0,2);
        world.setBlock(x+33, y+14, z+12,Blocks.hopper);
        world.setBlock(x+35, y+14, z+12,BlockRegistry.MAGIWOODPLANK);
        world.setBlock(x+39, y+14, z+12,BlockRegistry.MAGIWOODPLANK);
        world.setBlock(x+27, y+14, z+13,BlockRegistry.MAGIWOODLOG);
        world.setBlock(x+28, y+14, z+13,Blocks.redstone_torch);
        world.setBlock(x+31, y+14, z+13,BlockRegistry.MAGIWOODLOG);
        world.setBlock(x+30, y+14, z+13,Blocks.redstone_torch);
        world.setBlock(x+36, y+14, z+13,BlockRegistry.MAGIWOODPLANK);
        world.setBlock(x+38, y+14, z+13,BlockRegistry.MAGIWOODPLANK);
        world.setBlock(x+28, y+14, z+14,BlockRegistry.MAGIWOODLOG);
        world.setBlock(x+30, y+14, z+14,BlockRegistry.MAGIWOODLOG);
        world.setBlock(x+36, y+14, z+14,BlockRegistry.MAGIWOODPLANK);
        world.setBlock(x+38, y+14, z+14,BlockRegistry.MAGIWOODPLANK);
        world.setBlock(x+28, y+14, z+15,Blocks.hopper);
        world.setBlock(x+30, y+14, z+15,Blocks.hopper);
        world.setBlock(x+36, y+14, z+15,BlockRegistry.MAGIWOODPLANK);
        world.setBlock(x+38, y+14, z+15,BlockRegistry.MAGIWOODPLANK);
        world.setBlock(x+36, y+14, z+16,BlockRegistry.MAGIWOODPLANK);
        world.setBlock(x+37, y+14, z+16, Blocks.iron_door, 1, 2);
        world.setBlock(x+37, y + 15, z+16, Blocks.iron_door, 8, 2);
        world.setBlock(x+38, y+14, z+16,BlockRegistry.MAGIWOODPLANK);
        world.setBlock(x+35, y+14, z+17,BlockRegistry.MAGIWOODPLANK);
        world.setBlock(x+38, y+14, z+17,Blocks.obsidian);
        world.setBlock(x+39, y+14, z+17,BlockRegistry.MAGIWOODPLANK);
        world.setBlock(x+28, y+14, z+18,Blocks.bookshelf);
        world.setBlock(x+29, y+14, z+18,Blocks.bookshelf);
        world.setBlock(x+30, y+14, z+18,Blocks.bookshelf);
        world.setBlock(x+35, y+14, z+18,BlockRegistry.MAGIWOODPLANK);
        world.setBlock(x+38, y+14, z+18,Blocks.obsidian);
        world.setBlock(x+39, y+14, z+18,BlockRegistry.MAGIWOODPLANK);
        world.setBlock(x+27, y+14, z+19,Blocks.bookshelf);
        world.setBlock(x+31, y+14, z+19,Blocks.bookshelf);
        world.setBlock(x+35, y+14, z+19,BlockRegistry.MAGIWOODPLANK);
        world.setBlock(x+38, y+14, z+19,Blocks.obsidian);
        world.setBlock(x+39, y+14, z+19,BlockRegistry.MAGIWOODPLANK);
        world.setBlock(x+27, y+14, z+20,Blocks.bookshelf);
        world.setBlock(x+31, y+14, z+20,Blocks.bookshelf);
        world.setBlock(x+35, y+14, z+20,BlockRegistry.MAGIWOODPLANK);
        world.setBlock(x+38, y+14, z+20,Blocks.obsidian);
        world.setBlock(x+39, y+14, z+20,BlockRegistry.MAGIWOODPLANK);
        world.setBlock(x+27, y+14, z+21,Blocks.bookshelf);
        world.setBlock(x+31, y+14, z+21,Blocks.bookshelf);
        world.setBlock(x+35, y+14, z+21,BlockRegistry.MAGIWOODPLANK);
        world.setBlock(x+38, y+14, z+21,Blocks.obsidian);
        world.setBlock(x+39, y+14, z+21,BlockRegistry.MAGIWOODPLANK);
        world.setBlock(x+28, y+14, z+22,Blocks.bookshelf);
        world.setBlock(x+29, y+14, z+22,Blocks.bookshelf);
        world.setBlock(x+30, y+14, z+22,Blocks.bookshelf);
        world.setBlock(x+36, y+14, z+22,BlockRegistry.MAGIWOODPLANK);
        world.setBlock(x+37, y+14, z+22,BlockRegistry.MAGIWOODPLANK);
        world.setBlock(x+38, y+14, z+22,BlockRegistry.MAGIWOODPLANK);
        world.setBlock(x+37, y+14, z+15,Blocks.heavy_weighted_pressure_plate);
        world.setBlock(x+28, y+15, z+0 ,BlockRegistry.MAGIWOODPLANK);
        world.setBlock(x+29, y+15, z+0 ,BlockRegistry.MAGIWOODPLANK);
        world.setBlock(x+30, y+15, z+0 ,BlockRegistry.MAGIWOODPLANK);
        world.setBlock(x+27, y+15, z+1 ,BlockRegistry.MAGIWOODPLANK);
        world.setBlock(x+29, y+15, z+1 ,Blocks.redstone_torch);
        world.setBlock(x+31, y+15, z+1 ,BlockRegistry.MAGIWOODPLANK);
        world.setBlock(x+27, y+15, z+2 ,BlockRegistry.MAGIWOODPLANK);
        world.setBlock(x+28, y+15, z+2 ,Blocks.redstone_torch);
        world.setBlock(x+31, y+15, z+2 ,BlockRegistry.MAGIWOODPLANK);
        world.setBlock(x+30, y+15, z+2 ,Blocks.redstone_torch);
        world.setBlock(x+27, y+15, z+3 ,BlockRegistry.MAGIWOODPLANK);
        world.setBlock(x+31, y+15, z+3 ,BlockRegistry.MAGIWOODPLANK);
        world.setBlock(x+28, y+15, z+4 ,BlockRegistry.MAGIWOODPLANK);
        world.setBlock(x+29, y+15, z+4 ,BlockRegistry.MAGIWOODPLANK);
        world.setBlock(x+30, y+15, z+4 ,BlockRegistry.MAGIWOODPLANK);
        world.setBlock(x+28, y+15, z+6 ,Blocks.hopper,3,2);//insert
        world.setBlock(x+30, y+15, z+6 ,Blocks.hopper,3,2);//insert
        world.setBlock(x+28, y+15, z+7 ,Blocks.furnace);
        world.setBlock(x+30, y+15, z+7 ,Blocks.furnace);
        world.setBlock(x+28, y+15, z+8 ,BlockRegistry.MAGIWOODLOG);
        world.setBlock(x+30, y+15, z+8 ,BlockRegistry.MAGIWOODLOG);
        world.setBlock(x+27, y+15, z+9 ,BlockRegistry.MAGIWOODLOG);
        world.setBlock(x+31, y+15, z+9 ,BlockRegistry.MAGIWOODLOG);
        world.setBlock(x+36, y+15, z+9 ,BlockRegistry.MAGIWOODPLANK);
        world.setBlock(x+37, y+15, z+9 ,BlockRegistry.MAGIWOODPLANK);
        world.setBlock(x+38, y+15, z+9 ,BlockRegistry.MAGIWOODPLANK);
        world.setBlock(x+4 , y+15, z+10,Blocks.redstone_wire);
        world.setBlock(x+5 , y+15, z+10,Blocks.redstone_wire);
        world.setBlock(x+6 , y+15, z+10,Blocks.redstone_wire);
        world.setBlock(x+7 , y+15, z+10,Blocks.redstone_wire);
        world.setBlock(x+8 , y+15, z+10,Blocks.redstone_wire);
        world.setBlock(x+9 , y+15, z+10,Blocks.redstone_wire);
        world.setBlock(x+10, y+15, z+10,Blocks.redstone_wire);
        world.setBlock(x+11, y+15, z+10,Blocks.redstone_wire);
        world.setBlock(x+12, y+15, z+10,Blocks.redstone_wire);
        world.setBlock(x+13, y+15, z+10,Blocks.redstone_wire);
        world.setBlock(x+14, y+15, z+10,Blocks.redstone_wire);
        world.setBlock(x+15, y+15, z+10,Blocks.redstone_wire);
        world.setBlock(x+16, y+15, z+10,Blocks.redstone_wire);
        world.setBlock(x+17, y+15, z+10,Blocks.redstone_wire);
        world.setBlock(x+18, y+15, z+10,Blocks.redstone_wire);
        world.setBlock(x+19, y+15, z+10,BlockRegistry.HYPERSTEEL_ASSEMBLER_powered);
        world.setBlock(x+20, y+15, z+10,Blocks.hopper,4,2);//insert
        world.setBlock(x+24, y+15, z+10,Blocks.hopper,5,2);//insert
        world.setBlock(x+25, y+15, z+10,Blocks.furnace);
        world.setBlock(x+26, y+15, z+10,BlockRegistry.MAGIWOODLOG);
        world.setBlock(x+32, y+15, z+10,BlockRegistry.MAGIWOODLOG);
        world.setBlock(x+33, y+15, z+10,Blocks.furnace);
        world.setBlock(x+34, y+15, z+10,Blocks.hopper,4,2);//insert
        world.setBlock(x+35, y+15, z+10,BlockRegistry.MAGIWOODPLANK);
        world.setBlock(x+39, y+15, z+10,BlockRegistry.MAGIWOODPLANK);
        world.setBlock(x+5 , y+15, z+11,Blocks.redstone_block);
        world.setBlock(x+35, y+15, z+11,BlockRegistry.MAGIWOODPLANK);
        world.setBlock(x+36, y+15, z+11,Blocks.redstone_torch);
        world.setBlock(x+39, y+15, z+11,BlockRegistry.MAGIWOODPLANK);
        world.setBlock(x+38, y+15, z+11,Blocks.redstone_torch);
        world.setBlock(x+4 , y+15, z+12,Blocks.redstone_wire);
        world.setBlock(x+5 , y+15, z+12,Blocks.redstone_wire);
        world.setBlock(x+6 , y+15, z+12,Blocks.redstone_wire);
        world.setBlock(x+7 , y+15, z+12,Blocks.redstone_wire);
        world.setBlock(x+8 , y+15, z+12,Blocks.redstone_wire);
        world.setBlock(x+9 , y+15, z+12,Blocks.redstone_wire);
        world.setBlock(x+10, y+15, z+12,Blocks.redstone_wire);
        world.setBlock(x+11, y+15, z+12,Blocks.redstone_wire);
        world.setBlock(x+12, y+15, z+12,Blocks.redstone_wire);
        world.setBlock(x+13, y+15, z+12,Blocks.redstone_wire);
        world.setBlock(x+14, y+15, z+12,Blocks.redstone_wire);
        world.setBlock(x+15, y+15, z+12,Blocks.redstone_wire);
        world.setBlock(x+16, y+15, z+12,Blocks.redstone_wire);
        world.setBlock(x+17, y+15, z+12,Blocks.redstone_wire);
        world.setBlock(x+18, y+15, z+12,Blocks.redstone_wire);
        world.setBlock(x+19, y+15, z+12,BlockRegistry.HYPERSTEEL_ASSEMBLER_powered);
        world.setBlock(x+20, y+15, z+12,Blocks.hopper ,4,2);//insert
        world.setBlock(x+24, y+15, z+12,Blocks.hopper ,5,2);//insert
        world.setBlock(x+25, y+15, z+12,Blocks.furnace);
        world.setBlock(x+26, y+15, z+12,BlockRegistry.MAGIWOODLOG);
        world.setBlock(x+32, y+15, z+12,BlockRegistry.MAGIWOODLOG);
        world.setBlock(x+33, y+15, z+12,Blocks.furnace);
        world.setBlock(x+34, y+15, z+12,Blocks.hopper ,4,2);//insert
        world.setBlock(x+35, y+15, z+12,BlockRegistry.MAGIWOODPLANK);
        world.setBlock(x+39, y+15, z+12,BlockRegistry.MAGIWOODPLANK);
        world.setBlock(x+27, y+15, z+13,BlockRegistry.MAGIWOODLOG);
        world.setBlock(x+31, y+15, z+13,BlockRegistry.MAGIWOODLOG);
        world.setBlock(x+36, y+15, z+13,BlockRegistry.MAGIWOODPLANK);
        world.setBlock(x+38, y+15, z+13,BlockRegistry.MAGIWOODPLANK);
        world.setBlock(x+28, y+15, z+14,BlockRegistry.MAGIWOODLOG);
        world.setBlock(x+30, y+15, z+14,BlockRegistry.MAGIWOODLOG);
        world.setBlock(x+36, y+15, z+14,BlockRegistry.MAGIWOODPLANK);
        world.setBlock(x+37, y+15, z+14,Blocks.wall_sign,4,2);
        world.setBlock(x+38, y+15, z+14,BlockRegistry.MAGIWOODPLANK);
        world.setBlock(x+28, y+15, z+15,Blocks.furnace);
        world.setBlock(x+30, y+15, z+15,Blocks.furnace);
        world.setBlock(x+36, y+15, z+15,BlockRegistry.MAGIWOODPLANK);
        world.setBlock(x+38, y+15, z+15,BlockRegistry.MAGIWOODPLANK);
        world.setBlock(x+28, y+15, z+16,Blocks.hopper ,2,2);//insert
        world.setBlock(x+30, y+15, z+16,Blocks.hopper ,2,2);//insert
        world.setBlock(x+36, y+15, z+16,BlockRegistry.MAGIWOODPLANK);
        world.setBlock(x+29, y+15, z+3 ,Blocks.redstone_torch);
        world.setBlock(x+38, y+15, z+16,BlockRegistry.MAGIWOODPLANK);
        world.setBlock(x+35, y+15, z+17,BlockRegistry.MAGIWOODPLANK);
        world.setBlock(x+36, y+15, z+17,Blocks.wooden_button,3,0);
        world.setBlock(x+38, y+15, z+17,Blocks.obsidian);
        world.setBlock(x+39, y+15, z+17,BlockRegistry.MAGIWOODPLANK);
        world.setBlock(x+28, y+15, z+18,Blocks.bookshelf);
        world.setBlock(x+29, y+15, z+18,Blocks.bookshelf);
        world.setBlock(x+30, y+15, z+18,Blocks.bookshelf);
        world.setBlock(x+35, y+15, z+18,BlockRegistry.MAGIWOODPLANK);
        world.setBlock(x+39, y+15, z+18,BlockRegistry.MAGIWOODPLANK);
        world.setBlock(x+27, y+15, z+19,Blocks.bookshelf);
        world.setBlock(x+31, y+15, z+19,Blocks.bookshelf);
        world.setBlock(x+35, y+15, z+19,BlockRegistry.MAGIWOODPLANK);
        world.setBlock(x+39, y+15, z+19,BlockRegistry.MAGIWOODPLANK);
        world.setBlock(x+29, y+15, z+17,Blocks.redstone_torch);
        world.setBlock(x+27, y+15, z+20,Blocks.bookshelf);
        world.setBlock(x+31, y+15, z+20,Blocks.bookshelf);
        world.setBlock(x+35, y+15, z+20,BlockRegistry.MAGIWOODPLANK);
        world.setBlock(x+39, y+15, z+20,BlockRegistry.MAGIWOODPLANK);
        world.setBlock(x+27, y+15, z+21,Blocks.bookshelf);
        world.setBlock(x+31, y+15, z+21,Blocks.bookshelf);
        world.setBlock(x+35, y+15, z+21,BlockRegistry.MAGIWOODPLANK);
        world.setBlock(x+38, y+15, z+21,Blocks.obsidian);
        world.setBlock(x+39, y+15, z+21,BlockRegistry.MAGIWOODPLANK);
        world.setBlock(x+28, y+15, z+22,Blocks.bookshelf);
        world.setBlock(x+29, y+15, z+22,Blocks.bookshelf);
        world.setBlock(x+30, y+15, z+22,Blocks.bookshelf);
        world.setBlock(x+36, y+15, z+22,BlockRegistry.MAGIWOODPLANK);
        world.setBlock(x+37, y+15, z+22,BlockRegistry.MAGIWOODPLANK);
        world.setBlock(x+38, y+15, z+22,BlockRegistry.MAGIWOODPLANK);
        world.setBlock(x+28, y+16, z+1 ,BlockRegistry.MAGIWOODPLANK);
        world.setBlock(x+29, y+16, z+1 ,BlockRegistry.MAGIWOODPLANK);
        world.setBlock(x+30, y+16, z+1 ,BlockRegistry.MAGIWOODPLANK);
        world.setBlock(x+28, y+16, z+2 ,BlockRegistry.MAGIWOODPLANK);
        world.setBlock(x+29, y+16, z+2 ,Blocks.glowstone);
        world.setBlock(x+30, y+16, z+2 ,BlockRegistry.MAGIWOODPLANK);
        world.setBlock(x+28, y+16, z+3 ,BlockRegistry.MAGIWOODPLANK);
        world.setBlock(x+29, y+16, z+3 ,BlockRegistry.MAGIWOODPLANK);
        world.setBlock(x+30, y+16, z+3 ,BlockRegistry.MAGIWOODPLANK);
        world.setBlock(x+28, y+16, z+6 ,Blocks.chest);
        world.setBlock(x+30, y+16, z+6 ,Blocks.chest);
        world.setBlock(x+28, y+16, z+7 ,Blocks.hopper );//inserting into tile-entity
        world.setBlock(x+30, y+16, z+7 ,Blocks.hopper );//inserting into tile-entity
        world.setBlock(x+28, y+16, z+8 ,BlockRegistry.MAGIWOODLOG);
        world.setBlock(x+30, y+16, z+8 ,BlockRegistry.MAGIWOODLOG);
        world.setBlock(x+27, y+16, z+9 ,BlockRegistry.MAGIWOODLOG);
        world.setBlock(x+31, y+16, z+9 ,BlockRegistry.MAGIWOODLOG);
        world.setBlock(x+19, y+16, z+10,Blocks.hopper );//inserting into tile-entity
        world.setBlock(x+20, y+16, z+10,Blocks.chest);
        world.setBlock(x+24, y+16, z+10,Blocks.chest);
        world.setBlock(x+25, y+16, z+10,Blocks.hopper );//inserting into tile-entity
        world.setBlock(x+26, y+16, z+10,BlockRegistry.MAGIWOODLOG);
        world.setBlock(x+32, y+16, z+10,BlockRegistry.MAGIWOODLOG);
        world.setBlock(x+33, y+16, z+10,Blocks.hopper );//inserting into tile-entity
        world.setBlock(x+34, y+16, z+10,Blocks.chest);
        world.setBlock(x+36, y+16, z+10,BlockRegistry.MAGIWOODPLANK);
        world.setBlock(x+37, y+16, z+10,BlockRegistry.MAGIWOODPLANK);
        world.setBlock(x+38, y+16, z+10,BlockRegistry.MAGIWOODPLANK);
        world.setBlock(x+36, y+16, z+11,BlockRegistry.MAGIWOODPLANK);
        world.setBlock(x+37, y+16, z+11,Blocks.glowstone);
        world.setBlock(x+38, y+16, z+11,BlockRegistry.MAGIWOODPLANK);
        world.setBlock(x+19, y+16, z+12,Blocks.hopper );//inserting into tile-entity
        world.setBlock(x+20, y+16, z+12,Blocks.chest);
        world.setBlock(x+24, y+16, z+12,Blocks.chest);
        world.setBlock(x+25, y+16, z+12,Blocks.hopper );//inserting into tile-entity
        world.setBlock(x+26, y+16, z+12,BlockRegistry.MAGIWOODLOG);
        world.setBlock(x+32, y+16, z+12,BlockRegistry.MAGIWOODLOG);
        world.setBlock(x+33, y+16, z+12,Blocks.hopper );//inserting into tile-entity
        world.setBlock(x+34, y+16, z+12,Blocks.chest);
        world.setBlock(x+36, y+16, z+12,BlockRegistry.MAGIWOODPLANK);
        world.setBlock(x+37, y+16, z+12,BlockRegistry.MAGIWOODPLANK);
        world.setBlock(x+38, y+16, z+12,BlockRegistry.MAGIWOODPLANK);
        world.setBlock(x+27, y+16, z+13,BlockRegistry.MAGIWOODLOG);
        world.setBlock(x+31, y+16, z+13,BlockRegistry.MAGIWOODLOG);
        world.setBlock(x+37, y+16, z+13,BlockRegistry.MAGIWOODPLANK);
        world.setBlock(x+28, y+16, z+14,BlockRegistry.MAGIWOODLOG);
        world.setBlock(x+30, y+16, z+14,BlockRegistry.MAGIWOODLOG);
        world.setBlock(x+37, y+16, z+14,BlockRegistry.MAGIWOODPLANK);
        world.setBlock(x+28, y+16, z+15,Blocks.hopper );//inserting into tile-entity
        world.setBlock(x+30, y+16, z+15,Blocks.hopper );//inserting into tile-entity
        world.setBlock(x+37, y+16, z+15,BlockRegistry.MAGIWOODPLANK);
        world.setBlock(x+28, y+16, z+16,Blocks.chest);
        world.setBlock(x+30, y+16, z+16,Blocks.chest);
        world.setBlock(x+36, y+16, z+16,BlockRegistry.MAGIWOODPLANK);
        world.setBlock(x+37, y+16, z+16,BlockRegistry.MAGIWOODPLANK);
        world.setBlock(x+38, y+16, z+16,BlockRegistry.MAGIWOODPLANK);
        world.setBlock(x+35, y+16, z+17,BlockRegistry.MAGIWOODPLANK);
        world.setBlock(x+38, y+16, z+17,Blocks.obsidian);
        world.setBlock(x+39, y+16, z+17,BlockRegistry.MAGIWOODPLANK);
        world.setBlock(x+28, y+16, z+18,BlockRegistry.MAGIWOODPLANK);
        world.setBlock(x+30, y+16, z+18,BlockRegistry.MAGIWOODPLANK);
        world.setBlock(x+35, y+16, z+18,BlockRegistry.MAGIWOODPLANK);
        world.setBlock(x+39, y+16, z+18,BlockRegistry.MAGIWOODPLANK);
        world.setBlock(x+27, y+16, z+19,BlockRegistry.MAGIWOODPLANK);
        world.setBlock(x+31, y+16, z+19,BlockRegistry.MAGIWOODPLANK);
        world.setBlock(x+35, y+16, z+19,BlockRegistry.MAGIWOODPLANK);
        world.setBlock(x+39, y+16, z+19,BlockRegistry.MAGIWOODPLANK);
        world.setBlock(x+27, y+16, z+20,BlockRegistry.MAGIWOODPLANK);
        world.setBlock(x+31, y+16, z+20,BlockRegistry.MAGIWOODPLANK);
        world.setBlock(x+35, y+16, z+20,BlockRegistry.MAGIWOODPLANK);
        world.setBlock(x+39, y+16, z+20,BlockRegistry.MAGIWOODPLANK);
        world.setBlock(x+27, y+16, z+21,BlockRegistry.MAGIWOODPLANK);
        world.setBlock(x+31, y+16, z+21,BlockRegistry.MAGIWOODPLANK);
        world.setBlock(x+35, y+16, z+21,BlockRegistry.MAGIWOODPLANK);
        world.setBlock(x+38, y+16, z+21,Blocks.obsidian);
        world.setBlock(x+39, y+16, z+21,BlockRegistry.MAGIWOODPLANK);
        world.setBlock(x+28, y+16, z+22,BlockRegistry.MAGIWOODPLANK);
        world.setBlock(x+29, y+16, z+22,BlockRegistry.MAGIWOODPLANK);
        world.setBlock(x+30, y+16, z+22,BlockRegistry.MAGIWOODPLANK);
        world.setBlock(x+36, y+16, z+22,BlockRegistry.MAGIWOODPLANK);
        world.setBlock(x+37, y+16, z+22,BlockRegistry.MAGIWOODPLANK);
        world.setBlock(x+38, y+16, z+22,BlockRegistry.MAGIWOODPLANK);
        world.setBlock(x+28, y+17, z+7 ,Blocks.chest);
        world.setBlock(x+30, y+17, z+7 ,Blocks.chest);
        world.setBlock(x+28, y+17, z+8 ,BlockRegistry.MAGIWOODLOG);
        world.setBlock(x+30, y+17, z+8 ,BlockRegistry.MAGIWOODLOG);
        world.setBlock(x+27, y+17, z+9 ,BlockRegistry.MAGIWOODLOG);
        world.setBlock(x+31, y+17, z+9 ,BlockRegistry.MAGIWOODLOG);
        world.setBlock(x+19, y+17, z+10,Blocks.chest);
        world.setBlock(x+25, y+17, z+10,Blocks.chest);
        world.setBlock(x+26, y+17, z+10,BlockRegistry.MAGIWOODLOG);
        world.setBlock(x+32, y+17, z+10,BlockRegistry.MAGIWOODLOG);
        world.setBlock(x+33, y+17, z+10,Blocks.chest);
        world.setBlock(x+19, y+17, z+12,Blocks.chest);
        world.setBlock(x+25, y+17, z+12,Blocks.chest);
        world.setBlock(x+26, y+17, z+12,BlockRegistry.MAGIWOODLOG);
        world.setBlock(x+32, y+17, z+12,BlockRegistry.MAGIWOODLOG);
        world.setBlock(x+33, y+17, z+12,Blocks.chest);
        world.setBlock(x+27, y+17, z+13,BlockRegistry.MAGIWOODLOG);
        world.setBlock(x+31, y+17, z+13,BlockRegistry.MAGIWOODLOG);
        world.setBlock(x+28, y+17, z+14,BlockRegistry.MAGIWOODLOG);
        world.setBlock(x+30, y+17, z+14,BlockRegistry.MAGIWOODLOG);
        world.setBlock(x+28, y+17, z+15,Blocks.chest);
        world.setBlock(x+30, y+17, z+15,Blocks.chest);
        world.setBlock(x+36, y+17, z+16,BlockRegistry.MAGIWOODPLANK);
        world.setBlock(x+37, y+17, z+16,BlockRegistry.MAGIWOODPLANK);
        world.setBlock(x+38, y+17, z+16,BlockRegistry.MAGIWOODPLANK);
        world.setBlock(x+35, y+17, z+17,BlockRegistry.MAGIWOODPLANK);
        world.setBlock(x+38, y+17, z+17,Blocks.obsidian);
        world.setBlock(x+39, y+17, z+17,BlockRegistry.MAGIWOODPLANK);
        world.setBlock(x+28, y+17, z+18,BlockRegistry.MAGIWOODPLANK);
        world.setBlock(x+30, y+17, z+18,BlockRegistry.MAGIWOODPLANK);
        world.setBlock(x+35, y+17, z+18,BlockRegistry.MAGIWOODPLANK);
        world.setBlock(x+39, y+17, z+18,BlockRegistry.MAGIWOODPLANK);
        world.setBlock(x+27, y+17, z+19,BlockRegistry.MAGIWOODPLANK);
        world.setBlock(x+31, y+17, z+19,BlockRegistry.MAGIWOODPLANK);
        world.setBlock(x+35, y+17, z+19,BlockRegistry.MAGIWOODPLANK);
        world.setBlock(x+39, y+17, z+19,BlockRegistry.MAGIWOODPLANK);
        world.setBlock(x+27, y+17, z+20,BlockRegistry.MAGIWOODPLANK);
        world.setBlock(x+31, y+17, z+20,BlockRegistry.MAGIWOODPLANK);
        world.setBlock(x+35, y+17, z+20,BlockRegistry.MAGIWOODPLANK);
        world.setBlock(x+39, y+17, z+20,BlockRegistry.MAGIWOODPLANK);
        world.setBlock(x+27, y+17, z+21,BlockRegistry.MAGIWOODPLANK);
        world.setBlock(x+31, y+17, z+21,BlockRegistry.MAGIWOODPLANK);
        world.setBlock(x+35, y+17, z+21,BlockRegistry.MAGIWOODPLANK);
        world.setBlock(x+38, y+17, z+21,Blocks.obsidian);
        world.setBlock(x+39, y+17, z+21,BlockRegistry.MAGIWOODPLANK);
        world.setBlock(x+28, y+17, z+22,BlockRegistry.MAGIWOODPLANK);
        world.setBlock(x+29, y+17, z+22,BlockRegistry.MAGIWOODPLANK);
        world.setBlock(x+30, y+17, z+22,BlockRegistry.MAGIWOODPLANK);
        world.setBlock(x+36, y+17, z+22,BlockRegistry.MAGIWOODPLANK);
        world.setBlock(x+37, y+17, z+22,BlockRegistry.MAGIWOODPLANK);
        world.setBlock(x+38, y+17, z+22,BlockRegistry.MAGIWOODPLANK);
        world.setBlock(x+29, y+17, z+21,Blocks.redstone_torch);
        world.setBlock(x+28, y+18, z+8 ,BlockRegistry.MAGIWOODLOG);
        world.setBlock(x+29, y+18, z+8 ,BlockRegistry.MAGIWOODLOG);
        world.setBlock(x+30, y+18, z+8 ,BlockRegistry.MAGIWOODLOG);
        world.setBlock(x+27, y+18, z+9 ,BlockRegistry.MAGIWOODLOG);
        world.setBlock(x+31, y+18, z+9 ,BlockRegistry.MAGIWOODLOG);
        world.setBlock(x+26, y+18, z+10,BlockRegistry.MAGIWOODLOG);
        world.setBlock(x+32, y+18, z+10,BlockRegistry.MAGIWOODLOG);
        world.setBlock(x+26, y+18, z+11,BlockRegistry.MAGIWOODLOG);
        world.setBlock(x+32, y+18, z+11,BlockRegistry.MAGIWOODLOG);
        world.setBlock(x+26, y+18, z+12,BlockRegistry.MAGIWOODLOG);
        world.setBlock(x+32, y+18, z+12,BlockRegistry.MAGIWOODLOG);
        world.setBlock(x+27, y+18, z+13,BlockRegistry.MAGIWOODLOG);
        world.setBlock(x+31, y+18, z+13,BlockRegistry.MAGIWOODLOG);
        world.setBlock(x+28, y+18, z+14,BlockRegistry.MAGIWOODLOG);
        world.setBlock(x+29, y+18, z+14,BlockRegistry.MAGIWOODLOG);
        world.setBlock(x+30, y+18, z+14,BlockRegistry.MAGIWOODLOG);
        world.setBlock(x+36, y+18, z+16,BlockRegistry.MAGIWOODPLANK);
        world.setBlock(x+37, y+18, z+16,BlockRegistry.MAGIWOODPLANK);
        world.setBlock(x+38, y+18, z+16,BlockRegistry.MAGIWOODPLANK);
        world.setBlock(x+35, y+18, z+17,BlockRegistry.MAGIWOODPLANK);
        world.setBlock(x+36, y+18, z+17,Blocks.glowstone);
        world.setBlock(x+38, y+18, z+17,Blocks.obsidian);
        world.setBlock(x+39, y+18, z+17,BlockRegistry.MAGIWOODPLANK);
        world.setBlock(x+28, y+18, z+18,BlockRegistry.MAGIWOODPLANK);
        world.setBlock(x+29, y+18, z+18,BlockRegistry.MAGIWOODPLANK);
        world.setBlock(x+30, y+18, z+18,BlockRegistry.MAGIWOODPLANK);
        world.setBlock(x+35, y+18, z+18,BlockRegistry.MAGIWOODPLANK);
        world.setBlock(x+38, y+18, z+18,Blocks.obsidian);
        world.setBlock(x+39, y+18, z+18,BlockRegistry.MAGIWOODPLANK);
        world.setBlock(x+27, y+18, z+19,BlockRegistry.MAGIWOODPLANK);
        world.setBlock(x+31, y+18, z+19,BlockRegistry.MAGIWOODPLANK);
        world.setBlock(x+35, y+18, z+19,BlockRegistry.MAGIWOODPLANK);
        world.setBlock(x+38, y+18, z+19,Blocks.obsidian);
        world.setBlock(x+39, y+18, z+19,BlockRegistry.MAGIWOODPLANK);
        world.setBlock(x+27, y+18, z+20,BlockRegistry.MAGIWOODPLANK);
        world.setBlock(x+31, y+18, z+20,BlockRegistry.MAGIWOODPLANK);
        world.setBlock(x+35, y+18, z+20,BlockRegistry.MAGIWOODPLANK);
        world.setBlock(x+38, y+18, z+20,Blocks.obsidian);
        world.setBlock(x+39, y+18, z+20,BlockRegistry.MAGIWOODPLANK);
        world.setBlock(x+27, y+18, z+21,BlockRegistry.MAGIWOODPLANK);
        world.setBlock(x+31, y+18, z+21,BlockRegistry.MAGIWOODPLANK);
        world.setBlock(x+35, y+18, z+21,BlockRegistry.MAGIWOODPLANK);
        world.setBlock(x+36, y+18, z+21,Blocks.glowstone);
        world.setBlock(x+38, y+18, z+21,Blocks.obsidian);
        world.setBlock(x+39, y+18, z+21,BlockRegistry.MAGIWOODPLANK);
        world.setBlock(x+28, y+18, z+22,BlockRegistry.MAGIWOODPLANK);
        world.setBlock(x+29, y+18, z+22,BlockRegistry.MAGIWOODPLANK);
        world.setBlock(x+30, y+18, z+22,BlockRegistry.MAGIWOODPLANK);
        world.setBlock(x+36, y+18, z+22,BlockRegistry.MAGIWOODPLANK);
        world.setBlock(x+37, y+18, z+22,BlockRegistry.MAGIWOODPLANK);
        world.setBlock(x+38, y+18, z+22,BlockRegistry.MAGIWOODPLANK);
        world.setBlock(x+29, y+18, z+17,Blocks.redstone_torch);
        world.setBlock(x+28, y+19, z+8 ,BlockRegistry.MAGIWOODLOG);
        world.setBlock(x+29, y+19, z+8 ,BlockRegistry.MAGIWOODLOG);
        world.setBlock(x+30, y+19, z+8 ,BlockRegistry.MAGIWOODLOG);
        world.setBlock(x+27, y+19, z+9 ,BlockRegistry.MAGIWOODLOG);
        world.setBlock(x+31, y+19, z+9 ,BlockRegistry.MAGIWOODLOG);
        world.setBlock(x+26, y+19, z+10,BlockRegistry.MAGIWOODLOG);
        world.setBlock(x+32, y+19, z+10,BlockRegistry.MAGIWOODLOG);
        world.setBlock(x+26, y+19, z+11,BlockRegistry.MAGIWOODLOG);
        world.setBlock(x+32, y+19, z+11,BlockRegistry.MAGIWOODLOG);
        world.setBlock(x+26, y+19, z+12,BlockRegistry.MAGIWOODLOG);
        world.setBlock(x+32, y+19, z+12,BlockRegistry.MAGIWOODLOG);
        world.setBlock(x+27, y+19, z+13,BlockRegistry.MAGIWOODLOG);
        world.setBlock(x+31, y+19, z+13,BlockRegistry.MAGIWOODLOG);
        world.setBlock(x+28, y+19, z+14,BlockRegistry.MAGIWOODLOG);
        world.setBlock(x+29, y+19, z+14,BlockRegistry.MAGIWOODLOG);
        world.setBlock(x+30, y+19, z+14,BlockRegistry.MAGIWOODLOG);
        world.setBlock(x+36, y+19, z+17,BlockRegistry.MAGIWOODPLANK);
        world.setBlock(x+37, y+19, z+17,BlockRegistry.MAGIWOODPLANK);
        world.setBlock(x+38, y+19, z+17,BlockRegistry.MAGIWOODPLANK);
        world.setBlock(x+36, y+19, z+18,BlockRegistry.MAGIWOODPLANK);
        world.setBlock(x+37, y+19, z+18,BlockRegistry.MAGIWOODPLANK);
        world.setBlock(x+38, y+19, z+18,BlockRegistry.MAGIWOODPLANK);
        world.setBlock(x+28, y+19, z+19,BlockRegistry.MAGIWOODPLANK);
        world.setBlock(x+29, y+19, z+19,BlockRegistry.MAGIWOODPLANK);
        world.setBlock(x+30, y+19, z+19,BlockRegistry.MAGIWOODPLANK);
        world.setBlock(x+36, y+19, z+19,BlockRegistry.MAGIWOODPLANK);
        world.setBlock(x+37, y+19, z+19,BlockRegistry.MAGIWOODPLANK);
        world.setBlock(x+38, y+19, z+19,BlockRegistry.MAGIWOODPLANK);
        world.setBlock(x+28, y+19, z+20,BlockRegistry.MAGIWOODPLANK);
        world.setBlock(x+29, y+19, z+20,Blocks.glowstone);
        world.setBlock(x+30, y+19, z+20,BlockRegistry.MAGIWOODPLANK);
        world.setBlock(x+36, y+19, z+20,BlockRegistry.MAGIWOODPLANK);
        world.setBlock(x+37, y+19, z+20,BlockRegistry.MAGIWOODPLANK);
        world.setBlock(x+38, y+19, z+20,BlockRegistry.MAGIWOODPLANK);
        world.setBlock(x+28, y+19, z+21,BlockRegistry.MAGIWOODPLANK);
        world.setBlock(x+29, y+19, z+21,BlockRegistry.MAGIWOODPLANK);
        world.setBlock(x+30, y+19, z+21,BlockRegistry.MAGIWOODPLANK);
        world.setBlock(x+36, y+19, z+21,BlockRegistry.MAGIWOODPLANK);
        world.setBlock(x+37, y+19, z+21,BlockRegistry.MAGIWOODPLANK);
        world.setBlock(x+38, y+19, z+21,BlockRegistry.MAGIWOODPLANK);
        world.setBlock(x+28, y+20, z+8 ,BlockRegistry.LIGHTSTEEL_STAIRS,2,2);
        world.setBlock(x+29, y+20, z+8 ,BlockRegistry.LIGHTSTEEL_BLOCK);
        world.setBlock(x+30, y+20, z+8 ,BlockRegistry.LIGHTSTEEL_STAIRS,2,2);
        world.setBlock(x+27, y+20, z+9 ,BlockRegistry.MAGIWOODPLANK);
        world.setBlock(x+28, y+20, z+9 ,BlockRegistry.MAGIWOODPLANK);
        world.setBlock(x+29, y+20, z+9 ,BlockRegistry.MAGIWOODPLANK);
        world.setBlock(x+30, y+20, z+9 ,BlockRegistry.MAGIWOODPLANK);
        world.setBlock(x+31, y+20, z+9 ,BlockRegistry.MAGIWOODPLANK);
        world.setBlock(x+26, y+20, z+10,BlockRegistry.LIGHTSTEEL_STAIRS);
        world.setBlock(x+27, y+20, z+10,BlockRegistry.MAGIWOODPLANK);
        world.setBlock(x+28, y+20, z+10,BlockRegistry.MAGIWOODPLANK);
        world.setBlock(x+29, y+20, z+10,BlockRegistry.MAGIWOODPLANK);
        world.setBlock(x+30, y+20, z+10,BlockRegistry.MAGIWOODPLANK);
        world.setBlock(x+31, y+20, z+10,BlockRegistry.MAGIWOODPLANK);
        world.setBlock(x+32, y+20, z+10,BlockRegistry.LIGHTSTEEL_STAIRS,1,2);
        world.setBlock(x+26, y+20, z+11,BlockRegistry.LIGHTSTEEL_BLOCK);
        world.setBlock(x+27, y+20, z+11,BlockRegistry.MAGIWOODPLANK);
        world.setBlock(x+28, y+20, z+11,BlockRegistry.MAGIWOODPLANK);
        world.setBlock(x+29, y+20, z+11,Blocks.glowstone);
        world.setBlock(x+30, y+20, z+11,BlockRegistry.MAGIWOODPLANK);
        world.setBlock(x+31, y+20, z+11,BlockRegistry.MAGIWOODPLANK);
        world.setBlock(x+32, y+20, z+11,BlockRegistry.LIGHTSTEEL_BLOCK);
        world.setBlock(x+26, y+20, z+12,BlockRegistry.LIGHTSTEEL_STAIRS);
        world.setBlock(x+27, y+20, z+12,BlockRegistry.MAGIWOODPLANK);
        world.setBlock(x+28, y+20, z+12,BlockRegistry.MAGIWOODPLANK);
        world.setBlock(x+29, y+20, z+12,BlockRegistry.MAGIWOODPLANK);
        world.setBlock(x+30, y+20, z+12,BlockRegistry.MAGIWOODPLANK);
        world.setBlock(x+31, y+20, z+12,BlockRegistry.MAGIWOODPLANK);
        world.setBlock(x+32, y+20, z+12,BlockRegistry.LIGHTSTEEL_STAIRS,1,2);
        world.setBlock(x+27, y+20, z+13,BlockRegistry.MAGIWOODPLANK);
        world.setBlock(x+28, y+20, z+13,BlockRegistry.MAGIWOODPLANK);
        world.setBlock(x+29, y+20, z+13,BlockRegistry.MAGIWOODPLANK);
        world.setBlock(x+30, y+20, z+13,BlockRegistry.MAGIWOODPLANK);
        world.setBlock(x+31, y+20, z+13,BlockRegistry.MAGIWOODPLANK);
        world.setBlock(x+28, y+20, z+14,BlockRegistry.LIGHTSTEEL_STAIRS,3,2);
        world.setBlock(x+29, y+20, z+14,BlockRegistry.LIGHTSTEEL_BLOCK);
        world.setBlock(x+30, y+20, z+14,BlockRegistry.LIGHTSTEEL_STAIRS,3,2);
        world.setBlock(x+29, y+21, z+8 ,Blocks.heavy_weighted_pressure_plate);
        world.setBlock(x+27, y+21, z+9 ,BlockRegistry.MAGIWOODPLANK);
        world.setBlock(x+28, y+21, z+9 ,BlockRegistry.MAGIWOODPLANK);
        world.setBlock(x+29, y+21, z+9 ,Blocks.iron_door,1,2);
        world.setBlock(x+29, y+22, z+9 ,Blocks.iron_door,8,2);
        world.setBlock(x+30, y+21, z+9 ,BlockRegistry.MAGIWOODPLANK);
        world.setBlock(x+31, y+21, z+9 ,BlockRegistry.MAGIWOODPLANK);
        world.setBlock(x+27, y+21, z+10,BlockRegistry.MAGIWOODPLANK);
        world.setBlock(x+28, y+21, z+10,Blocks.chest);
        world.setBlock(x+30, y+21, z+10,Blocks.bed,0,2);
        world.setBlock(x+30, y+21, z+11,Blocks.bed,8,2);
        world.setBlock(x+31, y+21, z+10,BlockRegistry.MAGIWOODPLANK);
        world.setBlock(x+26, y+21, z+11,Blocks.heavy_weighted_pressure_plate);
        world.setBlock(x+27, y+21, z+11,Blocks.iron_door,0,2);
        world.setBlock(x+27, y+22, z+11,Blocks.iron_door,8,2);
        world.setBlock(x+31, y+21, z+11,BlockRegistry.MAGIWOODPLANK);
        world.setBlock(x+27, y+21, z+12,BlockRegistry.MAGIWOODPLANK);
        world.setBlock(x+28, y+21, z+12,Blocks.chest);
        world.setBlock(x+30, y+21, z+12,Blocks.chest);
        world.setBlock(x+31, y+21, z+12,BlockRegistry.MAGIWOODPLANK);
        world.setBlock(x+27, y+21, z+13,BlockRegistry.MAGIWOODPLANK);
        world.setBlock(x+28, y+21, z+13,BlockRegistry.MAGIWOODPLANK);
        world.setBlock(x+29, y+21, z+13,Blocks.iron_door,3,2);
        world.setBlock(x+29, y+22, z+13,Blocks.iron_door,8,2);
        world.setBlock(x+30, y+21, z+13,BlockRegistry.MAGIWOODPLANK);
        world.setBlock(x+31, y+21, z+13,BlockRegistry.MAGIWOODPLANK);
        world.setBlock(x+29, y+21, z+14,Blocks.heavy_weighted_pressure_plate);
        world.setBlock(x+27, y+22, z+9 ,BlockRegistry.MAGIWOODPLANK);
        world.setBlock(x+28, y+22, z+9 ,BlockRegistry.MAGIWOODPLANK);
        world.setBlock(x+30, y+22, z+9 ,BlockRegistry.MAGIWOODPLANK);
        world.setBlock(x+31, y+22, z+9 ,BlockRegistry.MAGIWOODPLANK);
        world.setBlock(x+27, y+22, z+10,BlockRegistry.MAGIWOODPLANK);
        world.setBlock(x+31, y+22, z+10,BlockRegistry.MAGIWOODPLANK);
        world.setBlock(x+31, y+22, z+11,BlockRegistry.MAGIWOODPLANK);
        world.setBlock(x+27, y+22, z+12,BlockRegistry.MAGIWOODPLANK);
        world.setBlock(x+31, y+22, z+12,BlockRegistry.MAGIWOODPLANK);
        world.setBlock(x+27, y+22, z+13,BlockRegistry.MAGIWOODPLANK);
        world.setBlock(x+28, y+22, z+13,BlockRegistry.MAGIWOODPLANK);
        world.setBlock(x+30, y+22, z+13,BlockRegistry.MAGIWOODPLANK);
        world.setBlock(x+31, y+22, z+13,BlockRegistry.MAGIWOODPLANK);
        world.setBlock(x+30, y+22, z+11,Blocks.redstone_torch);
        world.setBlock(x+28, y+22, z+10,Blocks.wooden_button,1,2);
        world.setBlock(x+30, y+22, z+10,Blocks.wooden_button,3,2);
        world.setBlock(x+28, y+22, z+12,Blocks.wooden_button,1,2);
        world.setBlock(x+30, y+22, z+12,Blocks.wooden_button,4,2);
        world.setBlock(x+27, y+23, z+9 ,BlockRegistry.MAGIWOODLEAVES);
        world.setBlock(x+28, y+23, z+9 ,BlockRegistry.MAGIWOODLEAVES);
        world.setBlock(x+29, y+23, z+9 ,BlockRegistry.MAGIWOODLEAVES);
        world.setBlock(x+30, y+23, z+9 ,BlockRegistry.MAGIWOODLEAVES);
        world.setBlock(x+31, y+23, z+9 ,BlockRegistry.MAGIWOODLEAVES);
        world.setBlock(x+27, y+23, z+10,BlockRegistry.MAGIWOODLEAVES);
        world.setBlock(x+28, y+23, z+10,BlockRegistry.MAGIWOODLEAVES);
        world.setBlock(x+29, y+23, z+10,BlockRegistry.MAGIWOODLEAVES);
        world.setBlock(x+30, y+23, z+10,BlockRegistry.MAGIWOODLEAVES);
        world.setBlock(x+31, y+23, z+10,BlockRegistry.MAGIWOODLEAVES);
        world.setBlock(x+27, y+23, z+11,BlockRegistry.MAGIWOODLEAVES);
        world.setBlock(x+28, y+23, z+11,BlockRegistry.MAGIWOODLEAVES);
        world.setBlock(x+29, y+23, z+11,BlockRegistry.MAGIWOODLEAVES);
        world.setBlock(x+30, y+23, z+11,BlockRegistry.MAGIWOODLEAVES);
        world.setBlock(x+31, y+23, z+11,BlockRegistry.MAGIWOODLEAVES);
        world.setBlock(x+27, y+23, z+12,BlockRegistry.MAGIWOODLEAVES);
        world.setBlock(x+28, y+23, z+12,BlockRegistry.MAGIWOODLEAVES);
        world.setBlock(x+29, y+23, z+12,BlockRegistry.MAGIWOODLEAVES);
        world.setBlock(x+30, y+23, z+12,BlockRegistry.MAGIWOODLEAVES);
        world.setBlock(x+31, y+23, z+12,BlockRegistry.MAGIWOODLEAVES);
        world.setBlock(x+27, y+23, z+13,BlockRegistry.MAGIWOODLEAVES);
        world.setBlock(x+28, y+23, z+13,BlockRegistry.MAGIWOODLEAVES);
        world.setBlock(x+29, y+23, z+13,BlockRegistry.MAGIWOODLEAVES);
        world.setBlock(x+30, y+23, z+13,BlockRegistry.MAGIWOODLEAVES);
        world.setBlock(x+31, y+23, z+13,BlockRegistry.MAGIWOODLEAVES);

        TileEntityChest c1 = (TileEntityChest) world.getTileEntity(x+20,y+16,z+10);
        if(c1!=null) {
            c1.setInventorySlotContents(0, new ItemStack(Items.quartz, 1));
            c1.setInventorySlotContents(1, new ItemStack(ItemRegistry.REDSTONE_HYPERCOIL, 1));
            c1.setInventorySlotContents(2, new ItemStack(Items.quartz, 1));
            c1.setInventorySlotContents(9,new ItemStack(Items.gold_ingot,1));
            c1.setInventorySlotContents(10,new ItemStack(Items.emerald,1));
            c1.setInventorySlotContents(11,new ItemStack(Items.gold_ingot,1));
            c1.setInventorySlotContents(18,new ItemStack(Items.quartz,1));
            c1.setInventorySlotContents(19,new ItemStack(Items.iron_ingot,1));
            c1.setInventorySlotContents(20,new ItemStack(Items.quartz,1));
        }
        TileEntityHopper h1 = (TileEntityHopper) world.getTileEntity(x+19,y+16,z+10);
        if(h1!=null){
            h1.setInventorySlotContents(0,new ItemStack(Items.redstone,1));
        }
        TileEntityHopper h2 = (TileEntityHopper) world.getTileEntity(x+19,y+14,z+10);
        if(h2!=null){
            h2.setInventorySlotContents(0,new ItemStack(Items.diamond,1));
        }
        TileEntityChest c2 = (TileEntityChest) world.getTileEntity(x+28,y+21,z+10);
        if(c2!=null) {
            c2.setInventorySlotContents(0,new ItemStack(Items.sugar,1));
            c2.setInventorySlotContents(1,new ItemStack(Items.feather,3));
            c2.setInventorySlotContents(8,new ItemStack(Items.feather,2));
            c2.setInventorySlotContents(14,new ItemStack(Items.feather,6));
            c2.setInventorySlotContents(18,new ItemStack(Items.feather,4));
            c2.setInventorySlotContents(20,new ItemStack(Items.feather,3));
            c2.setInventorySlotContents(26,new ItemStack(Items.feather,5));
        }
        TileEntityChest c3 = (TileEntityChest) world.getTileEntity(x+19,y+17,z+12);
        if(c3!=null) {
            c3.setInventorySlotContents(0,new ItemStack(Items.coal,1));
        }
        TileEntityChest c4 = (TileEntityChest) world.getTileEntity(x+20,y+16,z+12);
        if(c4!=null) {
            c4.setInventorySlotContents(1,new ItemStack(Items.coal,2));
            c4.setInventorySlotContents(9,new ItemStack(Items.coal,2));
            c4.setInventorySlotContents(10,new ItemStack(Blocks.coal_block,2));
            c4.setInventorySlotContents(11,new ItemStack(Items.coal,2));
            c4.setInventorySlotContents(19,new ItemStack(Items.coal,2));
        }
        TileEntityChest c5 = (TileEntityChest) world.getTileEntity(x+30,y+21,z+12);
        if(c5!=null) {
            c5.setInventorySlotContents(0,new ItemStack(Items.gold_ingot,1));
            c5.setInventorySlotContents(1,new ItemStack(Items.feather,2));
            c5.setInventorySlotContents(2,new ItemStack(Items.gold_ingot,1));
            c5.setInventorySlotContents(3,new ItemStack(Items.feather,1));
            c5.setInventorySlotContents(4,new ItemStack(Items.gold_ingot,1));
            c5.setInventorySlotContents(5,new ItemStack(Items.gold_ingot,1));
            c5.setInventorySlotContents(6,new ItemStack(Items.gold_ingot,1));
            c5.setInventorySlotContents(8,new ItemStack(Items.feather,5));
            c5.setInventorySlotContents(9,new ItemStack(Items.gold_ingot,1));
            c5.setInventorySlotContents(10,new ItemStack(Items.gold_ingot,1));
            c5.setInventorySlotContents(12,new ItemStack(Items.gold_ingot,1));
            c5.setInventorySlotContents(13,new ItemStack(Items.gold_ingot,1));
            c5.setInventorySlotContents(14,new ItemStack(Items.feather,1));
            c5.setInventorySlotContents(15,new ItemStack(Items.gold_ingot,1));
            c5.setInventorySlotContents(16,new ItemStack(Items.feather,2));
            c5.setInventorySlotContents(18,new ItemStack(Items.gold_ingot,1));
            c5.setInventorySlotContents(19,new ItemStack(Items.gold_ingot,1));
            c5.setInventorySlotContents(20,new ItemStack(Items.gold_ingot,1));
            c5.setInventorySlotContents(21,new ItemStack(Items.feather,2));
            c5.setInventorySlotContents(22,new ItemStack(Items.gold_ingot,1));
            c5.setInventorySlotContents(24,new ItemStack(Items.gold_ingot,1));
            c5.setInventorySlotContents(26,new ItemStack(Items.feather,1));
        }
        TileEntityHopper h3 = (TileEntityHopper) world.getTileEntity(x+19,y+14,z+12);
        if(h3!=null){
            h3.setInventorySlotContents(0,new ItemStack(Items.nether_star,1));
        }
        TileEntityChest c6 = (TileEntityChest) world.getTileEntity(x+28,y+21,z+12);
        if(c6!=null) {
            c6.setInventorySlotContents(0,new ItemStack(Items.gold_ingot,1));
            c6.setInventorySlotContents(1,new ItemStack(Items.gold_ingot,1));
            c6.setInventorySlotContents(2,new ItemStack(Items.gold_ingot,1));
            c6.setInventorySlotContents(4,new ItemStack(Items.gold_ingot,1));
            c6.setInventorySlotContents(5 ,new ItemStack(Items.feather,1));
            c6.setInventorySlotContents(6,new ItemStack(Items.gold_ingot,1));
            c6.setInventorySlotContents(9,new ItemStack(Items.gold_ingot,1));
            c6.setInventorySlotContents(10 ,new ItemStack(Items.feather,5));
            c6.setInventorySlotContents(11,new ItemStack(Items.gold_ingot,1));
            c6.setInventorySlotContents(12 ,new ItemStack(Items.feather,2));
            c6.setInventorySlotContents(13,new ItemStack(Items.gold_ingot,1));
            c6.setInventorySlotContents(15,new ItemStack(Items.gold_ingot,1));
            c6.setInventorySlotContents(17 ,new ItemStack(Items.feather,1));
            c6.setInventorySlotContents(18 ,new ItemStack(Items.feather,2));
            c6.setInventorySlotContents(19 ,new ItemStack(Items.feather,6));
            c6.setInventorySlotContents(23 ,new ItemStack(Items.feather,1));
            c6.setInventorySlotContents(25 ,new ItemStack(Items.feather,7));
        }
        TileEntitySign sign = (TileEntitySign) world.getTileEntity(x+37, y+15, z+14);
        if(sign!=null) {
            sign.signText[0] = "Nether portal";
            sign.signText[1] = "fire magic";
            sign.signText[2] = "should light it";
        }
        return true;
    }
}
